{"nodes":[{"content":"The exception that is thrown when an error occurs during an asynchronous operation.","nodes":[{"pos":[0,83],"content":"The exception that is thrown when an error occurs during an asynchronous operation.","nodes":[{"content":"The exception that is thrown when an error occurs during an asynchronous operation.","pos":[0,83]}]}],"pos":[948,1032],"yaml":true},{"content":"Initializes a new instance of the <xref href=\"System.IdentityModel.AsynchronousOperationException\"></xref> class.","nodes":[{"pos":[0,113],"content":"Initializes a new instance of the <ph id=\"ph1\">&lt;xref href=\"System.IdentityModel.AsynchronousOperationException\"&gt;&lt;/xref&gt;</ph> class.","source":"Initializes a new instance of the <xref href=\"System.IdentityModel.AsynchronousOperationException\"></xref> class."}],"pos":[3003,3117],"yaml":true},{"content":"This constructor initializes the <xref:System.Exception.Message%2A> property of the new instance to a system-supplied message that describes the error. This message takes into account the current system culture.  \n  \n The following table shows the initial property values for the new instance.  \n  \n|Property|Value|  \n|--------------|-----------|  \n|<xref:System.Exception.InnerException%2A>|`null`.|  \n|<xref:System.Exception.Message%2A>|The localized error message string.|","nodes":[{"pos":[0,211],"content":"This constructor initializes the <xref:System.Exception.Message%2A> property of the new instance to a system-supplied message that describes the error. This message takes into account the current system culture.","nodes":[{"content":"This constructor initializes the <xref:System.Exception.Message%2A> property of the new instance to a system-supplied message that describes the error. This message takes into account the current system culture.","pos":[0,211],"nodes":[{"content":"This constructor initializes the <ph id=\"ph1\">&lt;xref:System.Exception.Message%2A&gt;</ph> property of the new instance to a system-supplied message that describes the error.","pos":[0,151],"source":"This constructor initializes the <xref:System.Exception.Message%2A> property of the new instance to a system-supplied message that describes the error."},{"content":"This message takes into account the current system culture.","pos":[152,211]}]}]},{"pos":[218,293],"content":"The following table shows the initial property values for the new instance.","nodes":[{"content":"The following table shows the initial property values for the new instance.","pos":[0,75]}]},{"pos":[300,308],"content":"Property","nodes":[{"content":"Property","pos":[0,8]}]},{"pos":[309,314],"content":"Value","nodes":[{"content":"Value","pos":[0,5]}]},{"pos":[350,391],"content":"<xref:System.Exception.InnerException%2A>","nodes":[]},{"pos":[392,399],"content":"<ph id=\"ph1\">`null`</ph>.","source":"`null`."},{"pos":[404,438],"content":"<xref:System.Exception.Message%2A>","nodes":[]},{"pos":[439,474],"content":"The localized error message string.","nodes":[{"content":"The localized error message string.","pos":[0,35]}]}],"pos":[3128,3613],"yaml":true,"extradata":"MT"},{"content":"Initializes a new instance of the <xref href=\"System.IdentityModel.AsynchronousOperationException\"></xref> class with a system-supplied error message and a reference to the inner exception that is the cause of this exception.","nodes":[{"pos":[0,225],"content":"Initializes a new instance of the <ph id=\"ph1\">&lt;xref href=\"System.IdentityModel.AsynchronousOperationException\"&gt;&lt;/xref&gt;</ph> class with a system-supplied error message and a reference to the inner exception that is the cause of this exception.","source":"Initializes a new instance of the <xref href=\"System.IdentityModel.AsynchronousOperationException\"></xref> class with a system-supplied error message and a reference to the inner exception that is the cause of this exception."}],"pos":[4934,5160],"yaml":true},{"content":"An exception that is thrown as a direct result of a previous exception should include a reference to the previous exception in the <xref:System.Exception.InnerException%2A> property. The <xref:System.Exception.InnerException%2A> property returns the same value that is passed into the constructor.  \n  \n The following table shows the initial property values for the new instance.  \n  \n|Property|Value|  \n|--------------|-----------|  \n|<xref:System.Exception.InnerException%2A>|The inner exception reference.|  \n|<xref:System.Exception.Message%2A>|A system-supplied message that describes the error. This message takes into account the current system culture.|","nodes":[{"pos":[0,297],"content":"An exception that is thrown as a direct result of a previous exception should include a reference to the previous exception in the <xref:System.Exception.InnerException%2A> property. The <xref:System.Exception.InnerException%2A> property returns the same value that is passed into the constructor.","nodes":[{"content":"An exception that is thrown as a direct result of a previous exception should include a reference to the previous exception in the <xref:System.Exception.InnerException%2A> property. The <xref:System.Exception.InnerException%2A> property returns the same value that is passed into the constructor.","pos":[0,297],"nodes":[{"content":"An exception that is thrown as a direct result of a previous exception should include a reference to the previous exception in the <ph id=\"ph1\">&lt;xref:System.Exception.InnerException%2A&gt;</ph> property.","pos":[0,182],"source":"An exception that is thrown as a direct result of a previous exception should include a reference to the previous exception in the <xref:System.Exception.InnerException%2A> property."},{"content":"The <ph id=\"ph1\">&lt;xref:System.Exception.InnerException%2A&gt;</ph> property returns the same value that is passed into the constructor.","pos":[183,297],"source":" The <xref:System.Exception.InnerException%2A> property returns the same value that is passed into the constructor."}]}]},{"pos":[304,379],"content":"The following table shows the initial property values for the new instance.","nodes":[{"content":"The following table shows the initial property values for the new instance.","pos":[0,75]}]},{"pos":[386,394],"content":"Property","nodes":[{"content":"Property","pos":[0,8]}]},{"pos":[395,400],"content":"Value","nodes":[{"content":"Value","pos":[0,5]}]},{"pos":[436,477],"content":"<xref:System.Exception.InnerException%2A>","nodes":[]},{"pos":[478,508],"content":"The inner exception reference.","nodes":[{"content":"The inner exception reference.","pos":[0,30]}]},{"pos":[513,547],"content":"<xref:System.Exception.Message%2A>","nodes":[]},{"pos":[548,659],"content":"A system-supplied message that describes the error. This message takes into account the current system culture.","nodes":[{"content":"A system-supplied message that describes the error. This message takes into account the current system culture.","pos":[0,111],"nodes":[{"content":"A system-supplied message that describes the error.","pos":[0,51]},{"content":"This message takes into account the current system culture.","pos":[52,111]}]}]}],"pos":[5171,5841],"yaml":true,"extradata":"MT"},{"content":"The <xref href=\"System.Exception\"></xref> that is the cause of the current exception. If the <code>innerException</code> parameter is not `null`, the current exception is raised in a `catch` block that handles the inner exception.","nodes":[{"pos":[0,230],"content":"The <xref href=\"System.Exception\"></xref> that is the cause of the current exception. If the <code>innerException</code> parameter is not `null`, the current exception is raised in a `catch` block that handles the inner exception.","nodes":[{"content":"The <ph id=\"ph1\">&lt;xref href=\"System.Exception\"&gt;&lt;/xref&gt;</ph> that is the cause of the current exception.","pos":[0,85],"source":"The <xref href=\"System.Exception\"></xref> that is the cause of the current exception."},{"content":"If the <bpt id=\"p1\">&lt;code&gt;</bpt><ph id=\"ph1\">innerException</ph><ept id=\"p1\">&lt;/code&gt;</ept> parameter is not <ph id=\"ph2\">`null`</ph>, the current exception is raised in a <ph id=\"ph3\">`catch`</ph> block that handles the inner exception.","pos":[86,230],"source":" If the <code>innerException</code> parameter is not `null`, the current exception is raised in a `catch` block that handles the inner exception."}]}],"pos":[6019,6250],"yaml":true},{"content":"Initializes a new instance of the <xref href=\"System.IdentityModel.AsynchronousOperationException\"></xref> class with a specified error message.","nodes":[{"pos":[0,144],"content":"Initializes a new instance of the <ph id=\"ph1\">&lt;xref href=\"System.IdentityModel.AsynchronousOperationException\"&gt;&lt;/xref&gt;</ph> class with a specified error message.","source":"Initializes a new instance of the <xref href=\"System.IdentityModel.AsynchronousOperationException\"></xref> class with a specified error message."}],"pos":[7469,7614],"yaml":true},{"content":"This constructor initializes the <xref:System.Exception.Message%2A> property of the new exception using the `message` parameter. The content of `message` is intended to be understood by humans. The caller of this constructor is required to ensure that this string has been localized for the current system culture.  \n  \n The following table shows the initial property values for the new instance.  \n  \n|Property|Value|  \n|--------------|-----------|  \n|<xref:System.Exception.InnerException%2A>|`null`.|  \n|<xref:System.Exception.Message%2A>|The error message string.|","nodes":[{"pos":[0,314],"content":"This constructor initializes the <xref:System.Exception.Message%2A> property of the new exception using the `message` parameter. The content of `message` is intended to be understood by humans. The caller of this constructor is required to ensure that this string has been localized for the current system culture.","nodes":[{"content":"This constructor initializes the <ph id=\"ph1\">&lt;xref:System.Exception.Message%2A&gt;</ph> property of the new exception using the <ph id=\"ph2\">`message`</ph> parameter.","pos":[0,128],"source":"This constructor initializes the <xref:System.Exception.Message%2A> property of the new exception using the `message` parameter."},{"content":"The content of <ph id=\"ph1\">`message`</ph> is intended to be understood by humans.","pos":[129,193],"source":" The content of `message` is intended to be understood by humans."},{"content":"The caller of this constructor is required to ensure that this string has been localized for the current system culture.","pos":[194,314]}]},{"pos":[321,396],"content":"The following table shows the initial property values for the new instance.","nodes":[{"content":"The following table shows the initial property values for the new instance.","pos":[0,75]}]},{"pos":[403,411],"content":"Property","nodes":[{"content":"Property","pos":[0,8]}]},{"pos":[412,417],"content":"Value","nodes":[{"content":"Value","pos":[0,5]}]},{"pos":[453,494],"content":"<xref:System.Exception.InnerException%2A>","nodes":[]},{"pos":[495,502],"content":"<ph id=\"ph1\">`null`</ph>.","source":"`null`."},{"pos":[507,541],"content":"<xref:System.Exception.Message%2A>","nodes":[]},{"pos":[542,567],"content":"The error message string.","nodes":[{"content":"The error message string.","pos":[0,25]}]}],"pos":[7625,8203],"yaml":true,"extradata":"MT"},{"content":"The error message that explains the reason for the exception.","nodes":[{"pos":[0,61],"content":"The error message that explains the reason for the exception.","nodes":[{"content":"The error message that explains the reason for the exception.","pos":[0,61]}]}],"pos":[8361,8423],"yaml":true},{"content":"Initializes a new instance of the <xref href=\"System.IdentityModel.AsynchronousOperationException\"></xref> class with serialized data.","nodes":[{"pos":[0,134],"content":"Initializes a new instance of the <ph id=\"ph1\">&lt;xref href=\"System.IdentityModel.AsynchronousOperationException\"&gt;&lt;/xref&gt;</ph> class with serialized data.","source":"Initializes a new instance of the <xref href=\"System.IdentityModel.AsynchronousOperationException\"></xref> class with serialized data."}],"pos":[9966,10101],"yaml":true},{"content":"This constructor is called during deserialization to reconstitute the exception object transmitted over a stream.","nodes":[{"pos":[0,113],"content":"This constructor is called during deserialization to reconstitute the exception object transmitted over a stream.","nodes":[{"content":"This constructor is called during deserialization to reconstitute the exception object transmitted over a stream.","pos":[0,113]}]}],"pos":[10112,10226],"yaml":true,"extradata":"MT"},{"content":"A <xref href=\"System.Runtime.Serialization.SerializationInfo\"></xref> object that holds the serialized object data.","nodes":[{"pos":[0,115],"content":"A <ph id=\"ph1\">&lt;xref href=\"System.Runtime.Serialization.SerializationInfo\"&gt;&lt;/xref&gt;</ph> object that holds the serialized object data.","source":"A <xref href=\"System.Runtime.Serialization.SerializationInfo\"></xref> object that holds the serialized object data."}],"pos":[10509,10625],"yaml":true},{"content":"A <xref href=\"System.Runtime.Serialization.StreamingContext\"></xref> object that contains the contextual information about the source or destination.","nodes":[{"pos":[0,149],"content":"A <ph id=\"ph1\">&lt;xref href=\"System.Runtime.Serialization.StreamingContext\"&gt;&lt;/xref&gt;</ph> object that contains the contextual information about the source or destination.","source":"A <xref href=\"System.Runtime.Serialization.StreamingContext\"></xref> object that contains the contextual information about the source or destination."}],"pos":[10720,10870],"yaml":true},{"content":"Initializes a new instance of the <xref href=\"System.IdentityModel.AsynchronousOperationException\"></xref> class with a specified error message and a reference to the inner exception that is the cause of this exception.","nodes":[{"pos":[0,219],"content":"Initializes a new instance of the <ph id=\"ph1\">&lt;xref href=\"System.IdentityModel.AsynchronousOperationException\"&gt;&lt;/xref&gt;</ph> class with a specified error message and a reference to the inner exception that is the cause of this exception.","source":"Initializes a new instance of the <xref href=\"System.IdentityModel.AsynchronousOperationException\"></xref> class with a specified error message and a reference to the inner exception that is the cause of this exception."}],"pos":[12173,12393],"yaml":true},{"content":"An exception that is thrown as a direct result of a previous exception should include a reference to the previous exception in the <xref:System.Exception.InnerException%2A> property. The <xref:System.Exception.InnerException%2A> property returns the same value that is passed into the constructor.  \n  \n The following table shows the initial property values for the new instance.  \n  \n|Property|Value|  \n|--------------|-----------|  \n|<xref:System.Exception.InnerException%2A>|The inner exception reference.|  \n|<xref:System.Exception.Message%2A>|The error message string.|","nodes":[{"pos":[0,297],"content":"An exception that is thrown as a direct result of a previous exception should include a reference to the previous exception in the <xref:System.Exception.InnerException%2A> property. The <xref:System.Exception.InnerException%2A> property returns the same value that is passed into the constructor.","nodes":[{"content":"An exception that is thrown as a direct result of a previous exception should include a reference to the previous exception in the <xref:System.Exception.InnerException%2A> property. The <xref:System.Exception.InnerException%2A> property returns the same value that is passed into the constructor.","pos":[0,297],"nodes":[{"content":"An exception that is thrown as a direct result of a previous exception should include a reference to the previous exception in the <ph id=\"ph1\">&lt;xref:System.Exception.InnerException%2A&gt;</ph> property.","pos":[0,182],"source":"An exception that is thrown as a direct result of a previous exception should include a reference to the previous exception in the <xref:System.Exception.InnerException%2A> property."},{"content":"The <ph id=\"ph1\">&lt;xref:System.Exception.InnerException%2A&gt;</ph> property returns the same value that is passed into the constructor.","pos":[183,297],"source":" The <xref:System.Exception.InnerException%2A> property returns the same value that is passed into the constructor."}]}]},{"pos":[304,379],"content":"The following table shows the initial property values for the new instance.","nodes":[{"content":"The following table shows the initial property values for the new instance.","pos":[0,75]}]},{"pos":[386,394],"content":"Property","nodes":[{"content":"Property","pos":[0,8]}]},{"pos":[395,400],"content":"Value","nodes":[{"content":"Value","pos":[0,5]}]},{"pos":[436,477],"content":"<xref:System.Exception.InnerException%2A>","nodes":[]},{"pos":[478,508],"content":"The inner exception reference.","nodes":[{"content":"The inner exception reference.","pos":[0,30]}]},{"pos":[513,547],"content":"<xref:System.Exception.Message%2A>","nodes":[]},{"pos":[548,573],"content":"The error message string.","nodes":[{"content":"The error message string.","pos":[0,25]}]}],"pos":[12404,12988],"yaml":true,"extradata":"MT"},{"content":"The error message that explains the reason for the exception.","nodes":[{"pos":[0,61],"content":"The error message that explains the reason for the exception.","nodes":[{"content":"The error message that explains the reason for the exception.","pos":[0,61]}]}],"pos":[13172,13234],"yaml":true},{"content":"The <xref href=\"System.Exception\"></xref> that is the cause of the current exception. If the <code>innerException</code> parameter is not `null`, the current exception is raised in a `catch` block that handles the inner exception.","nodes":[{"pos":[0,230],"content":"The <xref href=\"System.Exception\"></xref> that is the cause of the current exception. If the <code>innerException</code> parameter is not `null`, the current exception is raised in a `catch` block that handles the inner exception.","nodes":[{"content":"The <ph id=\"ph1\">&lt;xref href=\"System.Exception\"&gt;&lt;/xref&gt;</ph> that is the cause of the current exception.","pos":[0,85],"source":"The <xref href=\"System.Exception\"></xref> that is the cause of the current exception."},{"content":"If the <bpt id=\"p1\">&lt;code&gt;</bpt><ph id=\"ph1\">innerException</ph><ept id=\"p1\">&lt;/code&gt;</ept> parameter is not <ph id=\"ph2\">`null`</ph>, the current exception is raised in a <ph id=\"ph3\">`catch`</ph> block that handles the inner exception.","pos":[86,230],"source":" If the <code>innerException</code> parameter is not `null`, the current exception is raised in a `catch` block that handles the inner exception."}]}],"pos":[13307,13538],"yaml":true}],"content":"### YamlMime:ManagedReference\nitems:\n- uid: System.IdentityModel.AsynchronousOperationException\n  commentId: T:System.IdentityModel.AsynchronousOperationException\n  id: AsynchronousOperationException\n  children:\n  - System.IdentityModel.AsynchronousOperationException.#ctor\n  - System.IdentityModel.AsynchronousOperationException.#ctor(System.Exception)\n  - System.IdentityModel.AsynchronousOperationException.#ctor(System.String)\n  - System.IdentityModel.AsynchronousOperationException.#ctor(System.Runtime.Serialization.SerializationInfo,System.Runtime.Serialization.StreamingContext)\n  - System.IdentityModel.AsynchronousOperationException.#ctor(System.String,System.Exception)\n  langs:\n  - csharp\n  name: AsynchronousOperationException\n  nameWithType: AsynchronousOperationException\n  fullName: System.IdentityModel.AsynchronousOperationException\n  type: Class\n  assemblies:\n  - System.IdentityModel\n  namespace: System.IdentityModel\n  summary: The exception that is thrown when an error occurs during an asynchronous operation.\n  syntax:\n    content: 'public class AsynchronousOperationException : Exception'\n  inheritance:\n  - System.Object\n  - System.Exception\n  implements: []\n  inheritedMembers:\n  - System.Exception.Data\n  - System.Exception.GetBaseException\n  - System.Exception.GetObjectData(System.Runtime.Serialization.SerializationInfo,System.Runtime.Serialization.StreamingContext)\n  - System.Exception.GetType\n  - System.Exception.HelpLink\n  - System.Exception.HResult\n  - System.Exception.InnerException\n  - System.Exception.Message\n  - System.Exception.SerializeObjectState\n  - System.Exception.Source\n  - System.Exception.StackTrace\n  - System.Exception.TargetSite\n  - System.Exception.ToString\n  - System.Object.Equals(System.Object)\n  - System.Object.Equals(System.Object,System.Object)\n  - System.Object.GetHashCode\n  - System.Object.MemberwiseClone\n  - System.Object.ReferenceEquals(System.Object,System.Object)\n  version:\n  - netframework-4.5.1\n  - netframework-4.5.2\n  - netframework-4.5\n  - netframework-4.6.1\n  - netframework-4.6.2\n  - netframework-4.6\n  - netframework-4.7\n  monikers:\n  - netframework-4.5.1\n  - netframework-4.5.2\n  - netframework-4.5\n  - netframework-4.6.1\n  - netframework-4.6.2\n  - netframework-4.6\n  - netframework-4.7\n  content_git_url: https://github.com/dotnet/docs/blob/master/xml/System.IdentityModel/AsynchronousOperationException.xml\n  ms.technology:\n  - dotnet-standard\n  ms.author: v-jibran\n  manager: markgal\n- uid: System.IdentityModel.AsynchronousOperationException.#ctor\n  commentId: M:System.IdentityModel.AsynchronousOperationException.#ctor\n  id: '#ctor'\n  parent: System.IdentityModel.AsynchronousOperationException\n  langs:\n  - csharp\n  name: AsynchronousOperationException()\n  nameWithType: AsynchronousOperationException.AsynchronousOperationException()\n  fullName: AsynchronousOperationException.AsynchronousOperationException()\n  type: Constructor\n  assemblies:\n  - System.IdentityModel\n  namespace: System.IdentityModel\n  summary: Initializes a new instance of the <xref href=\"System.IdentityModel.AsynchronousOperationException\"></xref> class.\n  remarks: \"This constructor initializes the <xref:System.Exception.Message%2A> property of the new instance to a system-supplied message that describes the error. This message takes into account the current system culture.  \\n  \\n The following table shows the initial property values for the new instance.  \\n  \\n|Property|Value|  \\n|--------------|-----------|  \\n|<xref:System.Exception.InnerException%2A>|`null`.|  \\n|<xref:System.Exception.Message%2A>|The localized error message string.|\"\n  syntax:\n    content: public AsynchronousOperationException ();\n    parameters: []\n  overload: System.IdentityModel.AsynchronousOperationException.#ctor*\n  exceptions: []\n  version:\n  - netframework-4.5.1\n  - netframework-4.5.2\n  - netframework-4.5\n  - netframework-4.6.1\n  - netframework-4.6.2\n  - netframework-4.6\n  - netframework-4.7\n  monikers:\n  - netframework-4.5.1\n  - netframework-4.5.2\n  - netframework-4.5\n  - netframework-4.6.1\n  - netframework-4.6.2\n  - netframework-4.6\n  - netframework-4.7\n  content_git_url: https://github.com/dotnet/docs/blob/master/xml/System.IdentityModel/AsynchronousOperationException.xml\n  ms.technology:\n  - dotnet-standard\n  ms.author: v-jibran\n  manager: markgal\n- uid: System.IdentityModel.AsynchronousOperationException.#ctor(System.Exception)\n  commentId: M:System.IdentityModel.AsynchronousOperationException.#ctor(System.Exception)\n  id: '#ctor(System.Exception)'\n  parent: System.IdentityModel.AsynchronousOperationException\n  langs:\n  - csharp\n  name: AsynchronousOperationException(Exception)\n  nameWithType: AsynchronousOperationException.AsynchronousOperationException(Exception)\n  fullName: AsynchronousOperationException.AsynchronousOperationException(Exception)\n  type: Constructor\n  assemblies:\n  - System.IdentityModel\n  namespace: System.IdentityModel\n  summary: Initializes a new instance of the <xref href=\"System.IdentityModel.AsynchronousOperationException\"></xref> class with a system-supplied error message and a reference to the inner exception that is the cause of this exception.\n  remarks: \"An exception that is thrown as a direct result of a previous exception should include a reference to the previous exception in the <xref:System.Exception.InnerException%2A> property. The <xref:System.Exception.InnerException%2A> property returns the same value that is passed into the constructor.  \\n  \\n The following table shows the initial property values for the new instance.  \\n  \\n|Property|Value|  \\n|--------------|-----------|  \\n|<xref:System.Exception.InnerException%2A>|The inner exception reference.|  \\n|<xref:System.Exception.Message%2A>|A system-supplied message that describes the error. This message takes into account the current system culture.|\"\n  syntax:\n    content: public AsynchronousOperationException (Exception innerException);\n    parameters:\n    - id: innerException\n      type: System.Exception\n      description: The <xref href=\"System.Exception\"></xref> that is the cause of the current exception. If the <code>innerException</code> parameter is not `null`, the current exception is raised in a `catch` block that handles the inner exception.\n  overload: System.IdentityModel.AsynchronousOperationException.#ctor*\n  exceptions: []\n  version:\n  - netframework-4.5.1\n  - netframework-4.5.2\n  - netframework-4.5\n  - netframework-4.6.1\n  - netframework-4.6.2\n  - netframework-4.6\n  - netframework-4.7\n  monikers:\n  - netframework-4.5.1\n  - netframework-4.5.2\n  - netframework-4.5\n  - netframework-4.6.1\n  - netframework-4.6.2\n  - netframework-4.6\n  - netframework-4.7\n  content_git_url: https://github.com/dotnet/docs/blob/master/xml/System.IdentityModel/AsynchronousOperationException.xml\n  ms.technology:\n  - dotnet-standard\n  ms.author: v-jibran\n  manager: markgal\n- uid: System.IdentityModel.AsynchronousOperationException.#ctor(System.String)\n  commentId: M:System.IdentityModel.AsynchronousOperationException.#ctor(System.String)\n  id: '#ctor(System.String)'\n  parent: System.IdentityModel.AsynchronousOperationException\n  langs:\n  - csharp\n  name: AsynchronousOperationException(String)\n  nameWithType: AsynchronousOperationException.AsynchronousOperationException(String)\n  fullName: AsynchronousOperationException.AsynchronousOperationException(String)\n  type: Constructor\n  assemblies:\n  - System.IdentityModel\n  namespace: System.IdentityModel\n  summary: Initializes a new instance of the <xref href=\"System.IdentityModel.AsynchronousOperationException\"></xref> class with a specified error message.\n  remarks: \"This constructor initializes the <xref:System.Exception.Message%2A> property of the new exception using the `message` parameter. The content of `message` is intended to be understood by humans. The caller of this constructor is required to ensure that this string has been localized for the current system culture.  \\n  \\n The following table shows the initial property values for the new instance.  \\n  \\n|Property|Value|  \\n|--------------|-----------|  \\n|<xref:System.Exception.InnerException%2A>|`null`.|  \\n|<xref:System.Exception.Message%2A>|The error message string.|\"\n  syntax:\n    content: public AsynchronousOperationException (string message);\n    parameters:\n    - id: message\n      type: System.String\n      description: The error message that explains the reason for the exception.\n  overload: System.IdentityModel.AsynchronousOperationException.#ctor*\n  exceptions: []\n  version:\n  - netframework-4.5.1\n  - netframework-4.5.2\n  - netframework-4.5\n  - netframework-4.6.1\n  - netframework-4.6.2\n  - netframework-4.6\n  - netframework-4.7\n  monikers:\n  - netframework-4.5.1\n  - netframework-4.5.2\n  - netframework-4.5\n  - netframework-4.6.1\n  - netframework-4.6.2\n  - netframework-4.6\n  - netframework-4.7\n  content_git_url: https://github.com/dotnet/docs/blob/master/xml/System.IdentityModel/AsynchronousOperationException.xml\n  ms.technology:\n  - dotnet-standard\n  ms.author: v-jibran\n  manager: markgal\n- uid: System.IdentityModel.AsynchronousOperationException.#ctor(System.Runtime.Serialization.SerializationInfo,System.Runtime.Serialization.StreamingContext)\n  commentId: M:System.IdentityModel.AsynchronousOperationException.#ctor(System.Runtime.Serialization.SerializationInfo,System.Runtime.Serialization.StreamingContext)\n  id: '#ctor(System.Runtime.Serialization.SerializationInfo,System.Runtime.Serialization.StreamingContext)'\n  parent: System.IdentityModel.AsynchronousOperationException\n  langs:\n  - csharp\n  name: AsynchronousOperationException(SerializationInfo, StreamingContext)\n  nameWithType: AsynchronousOperationException.AsynchronousOperationException(SerializationInfo, StreamingContext)\n  fullName: AsynchronousOperationException.AsynchronousOperationException(SerializationInfo, StreamingContext)\n  type: Constructor\n  assemblies:\n  - System.IdentityModel\n  namespace: System.IdentityModel\n  summary: Initializes a new instance of the <xref href=\"System.IdentityModel.AsynchronousOperationException\"></xref> class with serialized data.\n  remarks: This constructor is called during deserialization to reconstitute the exception object transmitted over a stream.\n  syntax:\n    content: protected AsynchronousOperationException (System.Runtime.Serialization.SerializationInfo info, System.Runtime.Serialization.StreamingContext context);\n    parameters:\n    - id: info\n      type: System.Runtime.Serialization.SerializationInfo\n      description: A <xref href=\"System.Runtime.Serialization.SerializationInfo\"></xref> object that holds the serialized object data.\n    - id: context\n      type: System.Runtime.Serialization.StreamingContext\n      description: A <xref href=\"System.Runtime.Serialization.StreamingContext\"></xref> object that contains the contextual information about the source or destination.\n  overload: System.IdentityModel.AsynchronousOperationException.#ctor*\n  exceptions: []\n  version:\n  - netframework-4.5.1\n  - netframework-4.5.2\n  - netframework-4.5\n  - netframework-4.6.1\n  - netframework-4.6.2\n  - netframework-4.6\n  - netframework-4.7\n  monikers:\n  - netframework-4.5.1\n  - netframework-4.5.2\n  - netframework-4.5\n  - netframework-4.6.1\n  - netframework-4.6.2\n  - netframework-4.6\n  - netframework-4.7\n  content_git_url: https://github.com/dotnet/docs/blob/master/xml/System.IdentityModel/AsynchronousOperationException.xml\n  ms.technology:\n  - dotnet-standard\n  ms.author: v-jibran\n  manager: markgal\n- uid: System.IdentityModel.AsynchronousOperationException.#ctor(System.String,System.Exception)\n  commentId: M:System.IdentityModel.AsynchronousOperationException.#ctor(System.String,System.Exception)\n  id: '#ctor(System.String,System.Exception)'\n  parent: System.IdentityModel.AsynchronousOperationException\n  langs:\n  - csharp\n  name: AsynchronousOperationException(String, Exception)\n  nameWithType: AsynchronousOperationException.AsynchronousOperationException(String, Exception)\n  fullName: AsynchronousOperationException.AsynchronousOperationException(String, Exception)\n  type: Constructor\n  assemblies:\n  - System.IdentityModel\n  namespace: System.IdentityModel\n  summary: Initializes a new instance of the <xref href=\"System.IdentityModel.AsynchronousOperationException\"></xref> class with a specified error message and a reference to the inner exception that is the cause of this exception.\n  remarks: \"An exception that is thrown as a direct result of a previous exception should include a reference to the previous exception in the <xref:System.Exception.InnerException%2A> property. The <xref:System.Exception.InnerException%2A> property returns the same value that is passed into the constructor.  \\n  \\n The following table shows the initial property values for the new instance.  \\n  \\n|Property|Value|  \\n|--------------|-----------|  \\n|<xref:System.Exception.InnerException%2A>|The inner exception reference.|  \\n|<xref:System.Exception.Message%2A>|The error message string.|\"\n  syntax:\n    content: public AsynchronousOperationException (string message, Exception innerException);\n    parameters:\n    - id: message\n      type: System.String\n      description: The error message that explains the reason for the exception.\n    - id: innerException\n      type: System.Exception\n      description: The <xref href=\"System.Exception\"></xref> that is the cause of the current exception. If the <code>innerException</code> parameter is not `null`, the current exception is raised in a `catch` block that handles the inner exception.\n  overload: System.IdentityModel.AsynchronousOperationException.#ctor*\n  exceptions: []\n  version:\n  - netframework-4.5.1\n  - netframework-4.5.2\n  - netframework-4.5\n  - netframework-4.6.1\n  - netframework-4.6.2\n  - netframework-4.6\n  - netframework-4.7\n  monikers:\n  - netframework-4.5.1\n  - netframework-4.5.2\n  - netframework-4.5\n  - netframework-4.6.1\n  - netframework-4.6.2\n  - netframework-4.6\n  - netframework-4.7\n  content_git_url: https://github.com/dotnet/docs/blob/master/xml/System.IdentityModel/AsynchronousOperationException.xml\n  ms.technology:\n  - dotnet-standard\n  ms.author: v-jibran\n  manager: markgal\nreferences:\n- uid: System.Exception\n  parent: System\n  isExternal: false\n  name: Exception\n  nameWithType: Exception\n  fullName: System.Exception\n- uid: System.IdentityModel.AsynchronousOperationException.#ctor\n  parent: System.IdentityModel.AsynchronousOperationException\n  isExternal: false\n  name: AsynchronousOperationException()\n  nameWithType: AsynchronousOperationException.AsynchronousOperationException()\n  fullName: AsynchronousOperationException.AsynchronousOperationException()\n- uid: System.IdentityModel.AsynchronousOperationException.#ctor(System.Exception)\n  parent: System.IdentityModel.AsynchronousOperationException\n  isExternal: false\n  name: AsynchronousOperationException(Exception)\n  nameWithType: AsynchronousOperationException.AsynchronousOperationException(Exception)\n  fullName: AsynchronousOperationException.AsynchronousOperationException(Exception)\n- uid: System.IdentityModel.AsynchronousOperationException.#ctor(System.String)\n  parent: System.IdentityModel.AsynchronousOperationException\n  isExternal: false\n  name: AsynchronousOperationException(String)\n  nameWithType: AsynchronousOperationException.AsynchronousOperationException(String)\n  fullName: AsynchronousOperationException.AsynchronousOperationException(String)\n- uid: System.String\n  parent: System\n  isExternal: false\n  name: String\n  nameWithType: String\n  fullName: System.String\n- uid: System.IdentityModel.AsynchronousOperationException.#ctor(System.Runtime.Serialization.SerializationInfo,System.Runtime.Serialization.StreamingContext)\n  parent: System.IdentityModel.AsynchronousOperationException\n  isExternal: false\n  name: AsynchronousOperationException(SerializationInfo, StreamingContext)\n  nameWithType: AsynchronousOperationException.AsynchronousOperationException(SerializationInfo, StreamingContext)\n  fullName: AsynchronousOperationException.AsynchronousOperationException(SerializationInfo, StreamingContext)\n- uid: System.Runtime.Serialization.SerializationInfo\n  parent: System.Runtime.Serialization\n  isExternal: false\n  name: SerializationInfo\n  nameWithType: SerializationInfo\n  fullName: System.Runtime.Serialization.SerializationInfo\n- uid: System.Runtime.Serialization.StreamingContext\n  parent: System.Runtime.Serialization\n  isExternal: false\n  name: StreamingContext\n  nameWithType: StreamingContext\n  fullName: System.Runtime.Serialization.StreamingContext\n- uid: System.IdentityModel.AsynchronousOperationException.#ctor(System.String,System.Exception)\n  parent: System.IdentityModel.AsynchronousOperationException\n  isExternal: false\n  name: AsynchronousOperationException(String, Exception)\n  nameWithType: AsynchronousOperationException.AsynchronousOperationException(String, Exception)\n  fullName: AsynchronousOperationException.AsynchronousOperationException(String, Exception)\n- uid: System.IdentityModel.AsynchronousOperationException.#ctor*\n  parent: System.IdentityModel.AsynchronousOperationException\n  isExternal: false\n  name: AsynchronousOperationException\n  nameWithType: AsynchronousOperationException.AsynchronousOperationException\n  fullName: AsynchronousOperationException.AsynchronousOperationException\n  monikers:\n  - netframework-4.5.1\n  - netframework-4.5.2\n  - netframework-4.5\n  - netframework-4.6.1\n  - netframework-4.6.2\n  - netframework-4.6\n  - netframework-4.7\n  content_git_url: https://github.com/dotnet/docs/blob/master/xml/System.IdentityModel/AsynchronousOperationException.xml\n- uid: System.Object.Equals(System.Object)\n  parent: System.Object\n  isExternal: false\n  name: Equals(Object)\n  nameWithType: Object.Equals(Object)\n  fullName: Object.Equals(Object)\n- uid: System.Object.Equals(System.Object,System.Object)\n  parent: System.Object\n  isExternal: false\n  name: Equals(Object, Object)\n  nameWithType: Object.Equals(Object, Object)\n  fullName: Object.Equals(Object, Object)\n- uid: System.Object.GetHashCode\n  parent: System.Object\n  isExternal: false\n  name: GetHashCode()\n  nameWithType: Object.GetHashCode()\n  fullName: Object.GetHashCode()\n- uid: System.Exception.GetType\n  parent: System.Exception\n  isExternal: false\n  name: GetType()\n  nameWithType: Exception.GetType()\n  fullName: Exception.GetType()\n- uid: System.Object.MemberwiseClone\n  parent: System.Object\n  isExternal: false\n  name: MemberwiseClone()\n  nameWithType: Object.MemberwiseClone()\n  fullName: Object.MemberwiseClone()\n- uid: System.Object.ReferenceEquals(System.Object,System.Object)\n  parent: System.Object\n  isExternal: false\n  name: ReferenceEquals(Object, Object)\n  nameWithType: Object.ReferenceEquals(Object, Object)\n  fullName: Object.ReferenceEquals(Object, Object)\n- uid: System.Exception.ToString\n  parent: System.Exception\n  isExternal: false\n  name: ToString()\n  nameWithType: Exception.ToString()\n  fullName: Exception.ToString()\n- uid: System.Exception.Data\n  parent: System.Exception\n  isExternal: false\n  name: Data\n  nameWithType: Exception.Data\n  fullName: Exception.Data\n- uid: System.Exception.GetBaseException\n  parent: System.Exception\n  isExternal: false\n  name: GetBaseException()\n  nameWithType: Exception.GetBaseException()\n  fullName: Exception.GetBaseException()\n- uid: System.Exception.GetObjectData(System.Runtime.Serialization.SerializationInfo,System.Runtime.Serialization.StreamingContext)\n  parent: System.Exception\n  isExternal: false\n  name: GetObjectData(SerializationInfo, StreamingContext)\n  nameWithType: Exception.GetObjectData(SerializationInfo, StreamingContext)\n  fullName: Exception.GetObjectData(SerializationInfo, StreamingContext)\n- uid: System.Exception.HelpLink\n  parent: System.Exception\n  isExternal: false\n  name: HelpLink\n  nameWithType: Exception.HelpLink\n  fullName: Exception.HelpLink\n- uid: System.Exception.HResult\n  parent: System.Exception\n  isExternal: false\n  name: HResult\n  nameWithType: Exception.HResult\n  fullName: Exception.HResult\n- uid: System.Exception.InnerException\n  parent: System.Exception\n  isExternal: false\n  name: InnerException\n  nameWithType: Exception.InnerException\n  fullName: Exception.InnerException\n- uid: System.Exception.Message\n  parent: System.Exception\n  isExternal: false\n  name: Message\n  nameWithType: Exception.Message\n  fullName: Exception.Message\n- uid: System.Exception.SerializeObjectState\n  parent: System.Exception\n  isExternal: false\n  name: SerializeObjectState\n  nameWithType: Exception.SerializeObjectState\n  fullName: Exception.SerializeObjectState\n- uid: System.Exception.Source\n  parent: System.Exception\n  isExternal: false\n  name: Source\n  nameWithType: Exception.Source\n  fullName: Exception.Source\n- uid: System.Exception.StackTrace\n  parent: System.Exception\n  isExternal: false\n  name: StackTrace\n  nameWithType: Exception.StackTrace\n  fullName: Exception.StackTrace\n- uid: System.Exception.TargetSite\n  parent: System.Exception\n  isExternal: false\n  name: TargetSite\n  nameWithType: Exception.TargetSite\n  fullName: Exception.TargetSite\n"}